[2025-09-21T07:02:29.175+0000] {taskinstance.py:1171} INFO - Dependencies all met for <TaskInstance: sql_to_elastic.fetchDB manual__2025-09-21T07:02:25.835411+00:00 [queued]>
[2025-09-21T07:02:29.195+0000] {taskinstance.py:1171} INFO - Dependencies all met for <TaskInstance: sql_to_elastic.fetchDB manual__2025-09-21T07:02:25.835411+00:00 [queued]>
[2025-09-21T07:02:29.195+0000] {taskinstance.py:1368} INFO - 
--------------------------------------------------------------------------------
[2025-09-21T07:02:29.195+0000] {taskinstance.py:1369} INFO - Starting attempt 1 of 1
[2025-09-21T07:02:29.196+0000] {taskinstance.py:1370} INFO - 
--------------------------------------------------------------------------------
[2025-09-21T07:02:29.213+0000] {taskinstance.py:1389} INFO - Executing <Task(PythonOperator): fetchDB> on 2025-09-21 07:02:25.835411+00:00
[2025-09-21T07:02:29.230+0000] {standard_task_runner.py:52} INFO - Started process 218 to run task
[2025-09-21T07:02:29.236+0000] {standard_task_runner.py:79} INFO - Running: ['***', 'tasks', 'run', 'sql_to_elastic', 'fetchDB', 'manual__2025-09-21T07:02:25.835411+00:00', '--job-id', '2', '--raw', '--subdir', 'DAGS_FOLDER/dag.py', '--cfg-path', '/tmp/tmpalt5ci4p', '--error-file', '/tmp/tmpy15c7wfb']
[2025-09-21T07:02:29.240+0000] {standard_task_runner.py:80} INFO - Job 2: Subtask fetchDB
[2025-09-21T07:02:29.357+0000] {task_command.py:371} INFO - Running <TaskInstance: sql_to_elastic.fetchDB manual__2025-09-21T07:02:25.835411+00:00 [running]> on host 05976e0e19d1
[2025-09-21T07:02:29.459+0000] {taskinstance.py:1583} INFO - Exporting the following env vars:
AIRFLOW_CTX_DAG_OWNER=***
AIRFLOW_CTX_DAG_ID=sql_to_elastic
AIRFLOW_CTX_TASK_ID=fetchDB
AIRFLOW_CTX_EXECUTION_DATE=2025-09-21T07:02:25.835411+00:00
AIRFLOW_CTX_TRY_NUMBER=1
AIRFLOW_CTX_DAG_RUN_ID=manual__2025-09-21T07:02:25.835411+00:00
[2025-09-21T07:02:29.483+0000] {taskinstance.py:1902} ERROR - Task failed with exception
Traceback (most recent call last):
  File "/home/airflow/.local/lib/python3.7/site-packages/airflow/operators/python.py", line 171, in execute
    return_value = self.execute_callable()
  File "/home/airflow/.local/lib/python3.7/site-packages/airflow/operators/python.py", line 189, in execute_callable
    return self.python_callable(*self.op_args, **self.op_kwargs)
  File "/opt/airflow/dags/dag.py", line 17, in fetchDB
    connection = pg_hook.get_conn()
  File "/home/airflow/.local/lib/python3.7/site-packages/airflow/providers/postgres/hooks/postgres.py", line 86, in get_conn
    conn = deepcopy(self.connection or self.get_connection(conn_id))
  File "/home/airflow/.local/lib/python3.7/site-packages/airflow/hooks/base.py", line 67, in get_connection
    conn = Connection.get_connection_from_secrets(conn_id)
  File "/home/airflow/.local/lib/python3.7/site-packages/airflow/models/connection.py", line 430, in get_connection_from_secrets
    raise AirflowNotFoundException(f"The conn_id `{conn_id}` isn't defined")
airflow.exceptions.AirflowNotFoundException: The conn_id `postgres_default` isn't defined
[2025-09-21T07:02:29.490+0000] {taskinstance.py:1412} INFO - Marking task as FAILED. dag_id=sql_to_elastic, task_id=fetchDB, execution_date=20250921T070225, start_date=20250921T070229, end_date=20250921T070229
[2025-09-21T07:02:29.499+0000] {standard_task_runner.py:97} ERROR - Failed to execute job 2 for task fetchDB (The conn_id `postgres_default` isn't defined; 218)
[2025-09-21T07:02:29.539+0000] {local_task_job.py:156} INFO - Task exited with return code 1
[2025-09-21T07:02:29.588+0000] {local_task_job.py:279} INFO - 0 downstream tasks scheduled from follow-on schedule check
