[2025-09-22T01:20:11.288+0000] {taskinstance.py:1171} INFO - Dependencies all met for <TaskInstance: sql_to_elastic.dataCleaning manual__2025-09-22T01:20:04.102475+00:00 [queued]>
[2025-09-22T01:20:11.317+0000] {taskinstance.py:1171} INFO - Dependencies all met for <TaskInstance: sql_to_elastic.dataCleaning manual__2025-09-22T01:20:04.102475+00:00 [queued]>
[2025-09-22T01:20:11.317+0000] {taskinstance.py:1368} INFO - 
--------------------------------------------------------------------------------
[2025-09-22T01:20:11.318+0000] {taskinstance.py:1369} INFO - Starting attempt 1 of 1
[2025-09-22T01:20:11.318+0000] {taskinstance.py:1370} INFO - 
--------------------------------------------------------------------------------
[2025-09-22T01:20:11.353+0000] {taskinstance.py:1389} INFO - Executing <Task(PythonOperator): dataCleaning> on 2025-09-22 01:20:04.102475+00:00
[2025-09-22T01:20:11.420+0000] {standard_task_runner.py:52} INFO - Started process 260 to run task
[2025-09-22T01:20:11.438+0000] {standard_task_runner.py:79} INFO - Running: ['***', 'tasks', 'run', 'sql_to_elastic', 'dataCleaning', 'manual__2025-09-22T01:20:04.102475+00:00', '--job-id', '11', '--raw', '--subdir', 'DAGS_FOLDER/dag.py', '--cfg-path', '/tmp/tmpppb1yxl8', '--error-file', '/tmp/tmp8f7ga_5f']
[2025-09-22T01:20:11.443+0000] {standard_task_runner.py:80} INFO - Job 11: Subtask dataCleaning
[2025-09-22T01:20:11.829+0000] {task_command.py:371} INFO - Running <TaskInstance: sql_to_elastic.dataCleaning manual__2025-09-22T01:20:04.102475+00:00 [running]> on host 05976e0e19d1
[2025-09-22T01:20:12.556+0000] {taskinstance.py:1583} INFO - Exporting the following env vars:
AIRFLOW_CTX_DAG_OWNER=***
AIRFLOW_CTX_DAG_ID=sql_to_elastic
AIRFLOW_CTX_TASK_ID=dataCleaning
AIRFLOW_CTX_EXECUTION_DATE=2025-09-22T01:20:04.102475+00:00
AIRFLOW_CTX_TRY_NUMBER=1
AIRFLOW_CTX_DAG_RUN_ID=manual__2025-09-22T01:20:04.102475+00:00
[2025-09-22T01:20:12.805+0000] {taskinstance.py:1902} ERROR - Task failed with exception
Traceback (most recent call last):
  File "/home/airflow/.local/lib/python3.7/site-packages/pandas/core/internals/construction.py", line 906, in _finalize_columns_and_data
    columns = _validate_or_indexify_columns(contents, columns)
  File "/home/airflow/.local/lib/python3.7/site-packages/pandas/core/internals/construction.py", line 955, in _validate_or_indexify_columns
    f"{len(columns)} columns passed, passed data had "
AssertionError: 2747 columns passed, passed data had 20 columns

The above exception was the direct cause of the following exception:

Traceback (most recent call last):
  File "/home/airflow/.local/lib/python3.7/site-packages/airflow/operators/python.py", line 171, in execute
    return_value = self.execute_callable()
  File "/home/airflow/.local/lib/python3.7/site-packages/airflow/operators/python.py", line 189, in execute_callable
    return self.python_callable(*self.op_args, **self.op_kwargs)
  File "/opt/airflow/dags/dag.py", line 32, in dataCleaning
    df = pd.DataFrame(data, columns=columnNames)
  File "/home/airflow/.local/lib/python3.7/site-packages/pandas/core/frame.py", line 700, in __init__
    dtype,
  File "/home/airflow/.local/lib/python3.7/site-packages/pandas/core/internals/construction.py", line 483, in nested_data_to_arrays
    arrays, columns = to_arrays(data, columns, dtype=dtype)
  File "/home/airflow/.local/lib/python3.7/site-packages/pandas/core/internals/construction.py", line 807, in to_arrays
    content, columns = _finalize_columns_and_data(arr, columns, dtype)
  File "/home/airflow/.local/lib/python3.7/site-packages/pandas/core/internals/construction.py", line 909, in _finalize_columns_and_data
    raise ValueError(err) from err
ValueError: 2747 columns passed, passed data had 20 columns
[2025-09-22T01:20:12.854+0000] {taskinstance.py:1412} INFO - Marking task as FAILED. dag_id=sql_to_elastic, task_id=dataCleaning, execution_date=20250922T012004, start_date=20250922T012011, end_date=20250922T012012
[2025-09-22T01:20:12.922+0000] {standard_task_runner.py:97} ERROR - Failed to execute job 11 for task dataCleaning (2747 columns passed, passed data had 20 columns; 260)
[2025-09-22T01:20:13.002+0000] {local_task_job.py:156} INFO - Task exited with return code 1
[2025-09-22T01:20:13.130+0000] {local_task_job.py:279} INFO - 0 downstream tasks scheduled from follow-on schedule check
